Workbook

Sheet シート1
A1: 表1
C2: 商品1曜日掛け率 | D2: 平均気温(℃) | E2: 気温偏差値 | F2: 最高気温(℃) | G2: 最高気温(℃)偏差値 | H2: 最低気温(℃) | I2: 最低気温(℃)偏差値 | J2: 降水量の合計(mm) | K2: 降水量の合計(mm)偏差値 | L2: 売上個数
A3: 43466 | B3: =WEEKDAY($A3) -> 3 | C3: =_xlfn.IFS(B3=1,1.5,B3=2,0.6,B3=3,0.8,B3=4,1,B3=5,0.8,B3=6,0.8,B3=7,1.2) -> 0.8 | D3: 5.3 | E3: =(((D3-AVERAGE(D$3:D$367))*10)/STDEVP(D$3:D$367))+50 -> 35.662271 | F3: 10.7 | G3: =(((F3-AVERAGE(F$3:F$367))*10)/STDEVP(F$3:F$367))+50 -> 37.151708 | H3: 0.9 | I3: =(((H3-AVERAGE(H$3:H$367))*10)/STDEVP(H$3:H$367))+50 -> 35.252794 | J3: 0 | K3: =(((J3-AVERAGE(J$3:J$367))*10)/STDEVP(J$3:J$367))+50 -> 47.055957 | L3: =MAX(INT(RAND()*30*C3+E3*30/50+G3*50/50+I3*10/50+I3*50/50-K3*100/50+100*C3),0) -> 106
A4: 43467 | B4: =WEEKDAY($A4) -> 4 | C4: =_xlfn.IFS(B4=1,1.5,B4=2,0.6,B4=3,0.8,B4=4,1,B4=5,0.8,B4=6,0.8,B4=7,1.2) -> 1 | D4: 6.2 | E4: =(((D4-AVERAGE(D$3:D$367))*10)/STDEVP(D$3:D$367))+50 -> 36.814945 | F4: 10.9 | G4: =(((F4-AVERAGE(F$3:F$367))*10)/STDEVP(F$3:F$367))+50 -> 37.402577 | H4: 2.2 | I4: =(((H4-AVERAGE(H$3:H$367))*10)/STDEVP(H$3:H$367))+50 -> 36.860465 | J4: 0 | K4: =(((J4-AVERAGE(J$3:J$367))*10)/STDEVP(J$3:J$367))+50 -> 47.055957 | L4: =MAX(INT(RAND()*30*C4+E4*30/50+G4*50/50+I4*10/50+I4*50/50-K4*90/50+100*C4),0) -> 141
A5: 43468 | B5: =WEEKDAY($A5) -> 5 | C5: =_xlfn.IFS(B5=1,1.5,B5=2,0.6,B5=3,0.8,B5=4,1,B5=5,0.8,B5=6,0.8,B5=7,1.2) -> 0.8 | D5: 4.9 | E5: =(((D5-AVERAGE(D$3:D$367))*10)/STDEVP(D$3:D$367))+50 -> 35.149971 | F5: 10.9 | G5: =(((F5-AVERAGE(F$3:F$367))*10)/STDEVP(F$3:F$367))+50 -> 37.402577 | H5: -0.3 | I5: =(((H5-AVERAGE(H$3:H$367))*10)/STDEVP(H$3:H$367))+50 -> 33.76879 | J5: 0 | K5: =(((J5-AVERAGE(J$3:J$367))*10)/STDEVP(J$3:J$367))+50 -> 47.055957 | L5: =MAX(INT(RAND()*30*C5+E5*30/50+G5*50/50+I5*10/50+I5*50/50-K5*90/50+100*C5),0) -> 111
A6: 43469 | B6: =WEEKDAY($A6) -> 6 | C6: =_xlfn.IFS(B6=1,1.5,B6=2,0.6,B6=3,0.8,B6=4,1,B6=5,0.8,B6=6,0.8,B6=7,1.2) -> 0.8 | D6: 5.1 | E6: =(((D6-AVERAGE(D$3:D$367))*10)/STDEVP(D$3:D$367))+50 -> 35.406121 | F6: 9.8 | G6: =(((F6-AVERAGE(F$3:F$367))*10)/STDEVP(F$3:F$367))+50 -> 36.022796 | H6: 0.2 | I6: =(((H6-AVERAGE(H$3:H$367))*10)/STDEVP(H$3:H$367))+50 -> 34.387125 | J6: 0 | K6: =(((J6-AVERAGE(J$3:J$367))*10)/STDEVP(J$3:J$367))+50 -> 47.055957 | L6: =MAX(INT(RAND()*30*C6+E6*30/50+G6*50/50+I6*10/50+I6*50/50-K6*90/50+100*C6),0) -> 114
A7: 43470 | B7: =WEEKDAY($A7) -> 7 | C7: =_xlfn.IFS(B7=1,1.5,B7=2,0.6,B7=3,0.8,B7=4,1,B7=5,0.8,B7=6,0.8,B7=7,1.2) -> 1.2 | D7: 7.4 | E7: =(((D7-AVERAGE(D$3:D$367))*10)/STDEVP(D$3:D$367))+50 -> 38.351845 | F7: 14 | G7: =(((F7-AVERAGE(F$3:F$367))*10)/STDEVP(F$3:F$367))+50 -> 41.291052 | H7: 0.9 | I7: =(((H7-AVERAGE(H$3:H$367))*10)/STDEVP(H$3:H$367))+50 -> 35.252794 | J7: 0 | K7: =(((J7-AVERAGE(J$3:J$367))*10)/STDEVP(J$3:J$367))+50 -> 47.055957 | L7: =MAX(INT(RAND()*30*C7+E7*30/50+G7*50/50+I7*10/50+I7*50/50-K7*90/50+100*C7),0) -> 144
A8: 43471 | B8: =WEEKDAY($A8) -> 1 | C8: =_xlfn.IFS(B8=1,1.5,B8=2,0.6,B8=3,0.8,B8=4,1,B8=5,0.8,B8=6,0.8,B8=7,1.2) -> 1.5 | D8: 5.3 | E8: =(((D8-AVERAGE(D$3:D$367))*10)/STDEVP(D$3:D$367))+50 -> 35.662271 | F8: 8 | G8: =(((F8-AVERAGE(F$3:F$367))*10)/STDEVP(F$3:F$367))+50 -> 33.764971 | H8: 2.4 | I8: =(((H8-AVERAGE(H$3:H$367))*10)/STDEVP(H$3:H$367))+50 -> 37.107799 | J8: 0 | K8: =(((J8-AVERAGE(J$3:J$367))*10)/STDEVP(J$3:J$367))+50 -> 47.055957 | L8: =MAX(INT(RAND()*30*C8+E8*30/50+G8*50/50+I8*10/50+I8*50/50-K8*90/50+100*C8),0) -> 204
A9: 43472 | B9: =WEEKDAY($A9) -> 2 | C9: =_xlfn.IFS(B9=1,1.5,B9=2,0.6,B9=3,0.8,B9=4,1,B9=5,0.8,B9=6,0.8,B9=7,1.2) -> 0.6 | D9: 5.4 | E9: =(((D9-AVERAGE(D$3:D$367))*10)/STDEVP(D$3:D$367))+50 -> 35.790346 | F9: 10.6 | G9: =(((F9-AVERAGE(F$3:F$367))*10)/STDEVP(F$3:F$367))+50 -> 37.026273 | H9: 0.4 | I9: =(((H9-AVERAGE(H$3:H$367))*10)/STDEVP(H$3:H$367))+50 -> 34.634459 | J9: 0 | K9: =(((J9-AVERAGE(J$3:J$367))*10)/STDEVP(J$3:J$367))+50 -> 47.055957 | L9: =MAX(INT(RAND()*30*C9+E9*30/50+G9*50/50+I9*10/50+I9*50/50-K9*90/50+100*C9),0) -> 84
A10: 43473 | B10: =WEEKDAY($A10) -> 3 | C10: =_xlfn.IFS(B10=1,1.5,B10=2,0.6,B10=3,0.8,B10=4,1,B10=5,0.8,B10=6,0.8,B10=7,1.2) -> 0.8 | D10: 4.6 | E10: =(((D10-AVERAGE(D$3:D$367))*10)/STDEVP(D$3:D$367))+50 -> 34.765746 | F10: 9.8 | G10: =(((F10-AVERAGE(F$3:F$367))*10)/STDEVP(F$3:F$367))+50 -> 36.022796 | H10: 0.7 | I10: =(((H10-AVERAGE(H$3:H$367))*10)/STDEVP(H$3:H$367))+50 -> 35.00546 | J10: 0 | K10: =(((J10-AVERAGE(J$3:J$367))*10)/STDEVP(J$3:J$367))+50 -> 47.055957 | L10: =MAX(INT(RAND()*30*C10+E10*30/50+G10*50/50+I10*10/50+I10*50/50-K10*90/50+100*C10),0) -> 95
A11: 43474 | B11: =WEEKDAY($A11) -> 4 | C11: =_xlfn.IFS(B11=1,1.5,B11=2,0.6,B11=3,0.8,B11=4,1,B11=5,0.8,B11=6,0.8,B11=7,1.2) -> 1 | D11: 4.5 | E11: =(((D11-AVERAGE(D$3:D$367))*10)/STDEVP(D$3:D$367))+50 -> 34.637671 | F11: 8 | G11: =(((F11-AVERAGE(F$3:F$367))*10)/STDEVP(F$3:F$367))+50 -> 33.764971 | H11: 1 | I11: =(((H11-AVERAGE(H$3:H$367))*10)/STDEVP(H$3:H$367))+50 -> 35.376461 | J11: 0 | K11: =(((J11-AVERAGE(J$3:J$367))*10)/STDEVP(J$3:J$367))+50 -> 47.055957 | L11: =MAX(INT(RAND()*30*C11+E11*30/50+G11*50/50+I11*10/50+I11*50/50-K11*90/50+100*C11),0) -> 124
A12: 43475 | B12: =WEEKDAY($A12) -> 5 | C12: =_xlfn.IFS(B12=1,1.5,B12=2,0.6,B12=3,0.8,B12=4,1,B12=5,0.8,B12=6,0.8,B12=7,1.2) -> 0.8 | D12: 2 | E12: =(((D12-AVERAGE(D$3:D$367))*10)/STDEVP(D$3:D$367))+50 -> 31.435797 | F12: 5.2 | G12: =(((F12-AVERAGE(F$3:F$367))*10)/STDEVP(F$3:F$367))+50 -> 30.2528 | H12: -1.2 | I12: =(((H12-AVERAGE(H$3:H$367))*10)/STDEVP(H$3:H$367))+50 -> 32.655787 | J12: 0 | K12: =(((J12-AVERAGE(J$3:J$367))*10)/STDEVP(J$3:J$367))+50 -> 47.055957 | L12: =MAX(INT(RAND()*30*C12+E12*30/50+G12*50/50+I12*10/50+I12*50/50-K12*90/50+100*C12),0) -> 91
A13: 43476 | B13: =WEEKDAY($A13) -> 6 | C13: =_xlfn.IFS(B13=1,1.5,B13=2,0.6,B13=3,0.8,B13=4,1,B13=5,0.8,B13=6,0.8,B13=7,1.2) -> 0.8 | D13: 6.4 | E13: =(((D13-AVERAGE(D$3:D$367))*10)/STDEVP(D$3:D$367))+50 -> 37.071095 | F13: 12.2 | G13: =(((F13-AVERAGE(F$3:F$367))*10)/STDEVP(F$3:F$367))+50 -> 39.033228 | H13: -0.2 | I13: =(((H13-AVERAGE(H$3:H$367))*10)/STDEVP(H$3:H$367))+50 -> 33.892457 | J13: 0 | K13: =(((J13-AVERAGE(J$3:J$367))*10)/STDEVP(J$3:J$367))+50 -> 47.055957 | L13: =MAX(INT(RAND()*30*C13+E13*30/50+G13*50/50+I13*10/50+I13*50/50-K13*90/50+100*C13),0) -> 114
A14: 43477 | B14: =WEEKDAY($A14) -> 7 | C14: =_xlfn.IFS(B14=1,1.5,B14=2,0.6,B14=3,0.8,B14=4,1,B14=5,0.8,B14=6,0.8,B14=7,1.2) -> 1.2 | D14: 4.6 | E14: =(((D14-AVERAGE(D$3:D$367))*10)/STDEVP(D$3:D$367))+50 -> 34.765746 | F14: 6.2 | G14: =(((F14-AVERAGE(F$3:F$367))*10)/STDEVP(F$3:F$367))+50 -> 31.507147 | H14: 2.7 | I14: =(((H14-AVERAGE(H$3:H$367))*10)/STDEVP(H$3:H$367))+50 -> 37.4788 | J14: 0 | K14: =(((J14-AVERAGE(J$3:J$367))*10)/STDEVP(J$3:J$367))+50 -> 47.055957 | L14: =MAX(INT(RAND()*30*C14+E14*30/50+G14*50/50+I14*10/50+I14*50/50-K14*90/50+100*C14),0) -> 157
A15: 43478 | B15: =WEEKDAY($A15) -> 1 | C15: =_xlfn.IFS(B15=1,1.5,B15=2,0.6,B15=3,0.8,B15=4,1,B15=5,0.8,B15=6,0.8,B15=7,1.2) -> 1.5 | D15: 6.2 | E15: =(((D15-AVERAGE(D$3:D$367))*10)/STDEVP(D$3:D$367))+50 -> 36.814945 | F15: 10.1 | G15: =(((F15-AVERAGE(F$3:F$367))*10)/STDEVP(F$3:F$367))+50 -> 36.3991 | H15: 3.9 | I15: =(((H15-AVERAGE(H$3:H$367))*10)/STDEVP(H$3:H$367))+50 -> 38.962804 | J15: 0 | K15: =(((J15-AVERAGE(J$3:J$367))*10)/STDEVP(J$3:J$367))+50 -> 47.055957 | L15: =MAX(INT(RAND()*30*C15+E15*30/50+G15*50/50+I15*10/50+I15*50/50-K15*90/50+100*C15),0) -> 215
... A367: 43830 | B367: =WEEKDAY($A367) -> 3 | C367: =_xlfn.IFS(B367=1,1.5,B367=2,0.6,B367=3,0.8,B367=4,1,B367=5,0.8,B367=6,0.8,B367=7,1.2) -> 0.8 | D367: 8.2 | E367: =(((D367-AVERAGE(D$3:D$367))*10)/STDEVP(D$3:D$367))+50 -> 39.376445 | F367: 16.5 | G367: =(((F367-AVERAGE(F$3:F$367))*10)/STDEVP(F$3:F$367))+50 -> 44.42692 | H367: 3.7 | I367: =(((H367-AVERAGE(H$3:H$367))*10)/STDEVP(H$3:H$367))+50 -> 38.71547 | J367: 0 | K367: =(((J367-AVERAGE(J$3:J$367))*10)/STDEVP(J$3:J$367))+50 -> 47.055957 | L367: =MAX(INT(RAND()*30*C367+E367*30/50+G367*50/50+I367*10/50+I367*50/50-K367*90/50+100*C367),0) -> 119

Sheet アイスクリームの売り上げデータ
A1: 表1
B2: 曜日 1:日 2:月 3:火 4:水 5:木 6:金 7:土 | C2: 平均気温(℃) | D2: 最高気温(℃) | E2: 最低気温(℃) | F2: 降水量の合計(mm) | G2: 売上個数
A3: 43466 | B3: =WEEKDAY($A3) -> 3 | C3: 5.3 | D3: 10.7 | E3: 0.9 | F3: 0 | G3: 101
A4: 43467 | B4: =WEEKDAY($A4) -> 4 | C4: 6.2 | D4: 10.9 | E4: 2.2 | F4: 0 | G4: 119
A5: 43468 | B5: =WEEKDAY($A5) -> 5 | C5: 4.9 | D5: 10.9 | E5: -0.3 | F5: 0 | G5: 98
A6: 43469 | B6: =WEEKDAY($A6) -> 6 | C6: 5.1 | D6: 9.8 | E6: 0.2 | F6: 0 | G6: 106
A7: 43470 | B7: =WEEKDAY($A7) -> 7 | C7: 7.4 | D7: 14 | E7: 0.9 | F7: 0 | G7: 174
A8: 43471 | B8: =WEEKDAY($A8) -> 1 | C8: 5.3 | D8: 8 | E8: 2.4 | F8: 0 | G8: 206
A9: 43472 | B9: =WEEKDAY($A9) -> 2 | C9: 5.4 | D9: 10.6 | E9: 0.4 | F9: 0 | G9: 90
A10: 43473 | B10: =WEEKDAY($A10) -> 3 | C10: 4.6 | D10: 9.8 | E10: 0.7 | F10: 0 | G10: 110
A11: 43474 | B11: =WEEKDAY($A11) -> 4 | C11: 4.5 | D11: 8 | E11: 1 | F11: 0 | G11: 117
A12: 43475 | B12: =WEEKDAY($A12) -> 5 | C12: 2 | D12: 5.2 | E12: -1.2 | F12: 0 | G12: 104
A13: 43476 | B13: =WEEKDAY($A13) -> 6 | C13: 6.4 | D13: 12.2 | E13: -0.2 | F13: 0 | G13: 117
A14: 43477 | B14: =WEEKDAY($A14) -> 7 | C14: 4.6 | D14: 6.2 | E14: 2.7 | F14: 0 | G14: 161
... A367: 43830 | B367: =WEEKDAY($A367) -> 3 | C367: 8.2 | D367: 16.5 | E367: 3.7 | F367: 0 | G367: 117

Sheet 曜日毎データ
B2: 曜日 | C2: 合計売上個数
B3: 日曜日 | C3: =SUMIF(アイスクリームの売り上げデータ!$B3:$B367, "=1", アイスクリームの売り上げデータ!$G3:$G367) -> 11641
B4: 月曜日 | C4: =SUMIF(アイスクリームの売り上げデータ!$B4:$B368, "=2", アイスクリームの売り上げデータ!$G4:$G368) -> 5982
B5: 火曜日 | C5: =SUMIF(アイスクリームの売り上げデータ!$B5:$B369, "=3", アイスクリームの売り上げデータ!$G5:$G369) -> 7383
B6: 水曜日 | C6: =SUMIF(アイスクリームの売り上げデータ!$B6:$B370, "=4", アイスクリームの売り上げデータ!$G6:$G370) -> 8601
B7: 木曜日 | C7: =SUMIF(アイスクリームの売り上げデータ!$B7:$B371, "=5", アイスクリームの売り上げデータ!$G7:$G371) -> 7393
B8: 金曜日 | C8: =SUMIF(アイスクリームの売り上げデータ!$B8:$B372, "=6", アイスクリームの売り上げデータ!$G8:$G372) -> 7171
B9: 土曜日 | C9: =SUMIF(アイスクリームの売り上げデータ!$B9:$B373, "=7", アイスクリームの売り上げデータ!$G9:$G373) -> 9406
B11: 日曜日 | C11: 月曜日 | D11: 火曜日 | E11: 水曜日 | F11: 木曜日 | G11: 金曜日 | H11: 土曜日
B12: {=_xlfn._xlws.FILTER(アイスクリームの売り上げデータ!$G3:$G367, アイスクリームの売り上げデータ!$B3:$B367=1)} -> 206 | C12: {=_xlfn._xlws.FILTER(アイスクリームの売り上げデータ!$G3:$G367, アイスクリームの売り上げデータ!$B3:$B367=2)} -> 90 | D12: {=_xlfn._xlws.FILTER(アイスクリームの売り上げデータ!$G3:$G367, アイスクリームの売り上げデータ!$B3:$B367=3)} -> 101 | E12: {=_xlfn._xlws.FILTER(アイスクリームの売り上げデータ!$G3:$G367, アイスクリームの売り上げデータ!$B3:$B367=4)} -> 119 | F12: {=_xlfn._xlws.FILTER(アイスクリームの売り上げデータ!$G3:$G367, アイスクリームの売り上げデータ!$B3:$B367=5)} -> 98 | G12: {=_xlfn._xlws.FILTER(アイスクリームの売り上げデータ!$G3:$G367, アイスクリームの売り上げデータ!$B3:$B367=6)} -> 106 | H12: {=_xlfn._xlws.FILTER(アイスクリームの売り上げデータ!$G3:$G367, アイスクリームの売り上げデータ!$B3:$B367=7)} -> 174
B13: 176 | C13: 87 | D13: 110 | E13: 117 | F13: 104 | G13: 117 | H13: 161
B14: 187 | C14: 90 | D14: 100 | E14: 130 | F14: 117 | G14: 102 | H14: 160
B15: 170 | C15: 80 | D15: 98 | E15: 139 | F15: 112 | G15: 111 | H15: 152
B16: 176 | C16: 114 | D16: 115 | E16: 120 | F16: 94 | G16: 97 | H16: 149
B17: 162 | C17: 81 | D17: 122 | E17: 119 | F17: 123 | G17: 110 | H17: 125
B18: 186 | C18: 90 | D18: 101 | E18: 124 | F18: 97 | G18: 98 | H18: 166
B19: 182 | C19: 109 | D19: 127 | E19: 165 | F19: 115 | G19: 125 | H19: 173
B20: 158 | C20: 58 | D20: 116 | E20: 143 | F20: 86 | G20: 110 | H20: 166
B21: 207 | C21: 79 | D21: 134 | E21: 150 | F21: 86 | G21: 126 | H21: 154
B22: 222 | C22: 100 | D22: 132 | E22: 140 | F22: 109 | G22: 120 | H22: 164
B23: 218 | C23: 91 | D23: 134 | E23: 158 | F23: 140 | G23: 136 | H23: 156
B24: 220 | C24: 89 | D24: 126 | E24: 162 | F24: 137 | G24: 105 | H24: 171
... B63: 199 | C63: 88 | D63: 120 | E63: 143 | F63: 107 | G63: 125 | H63: 168
D64: 117
B66: 日曜日 | C66: 月曜日 | D66: 火曜日 | E66: 水曜日 | F66: 木曜日 | G66: 金曜日 | H66: 土曜日
A67: 個数 | B67: =COUNT(B12:B64) -> 52 | C67: =COUNT(C12:C64) -> 52 | D67: =COUNT(D12:D64) -> 53 | E67: =COUNT(E12:E64) -> 52 | F67: =COUNT(F12:F64) -> 52 | G67: =COUNT(G12:G64) -> 52 | H67: =COUNT(H12:H64) -> 52
A68: 平均値 | B68: =AVERAGE(B12:B64) -> 223.86538 | C68: =AVERAGE(C12:C64) -> 115.03846 | D68: =AVERAGE(D12:D64) -> 141.20755 | E68: =AVERAGE(E12:E64) -> 167.69231 | F68: =AVERAGE(F12:F64) -> 144.05769 | G68: =AVERAGE(G12:G64) -> 139.94231 | H68: =AVERAGE(H12:H64) -> 184.23077
A69: 最小値 | B69: =MIN(B12:B64) -> 157 | C69: =MIN(C12:C64) -> 31 | D69: =MIN(D12:D64) -> 69 | E69: =MIN(E12:E64) -> 100 | F69: =MIN(F12:F64) -> 86 | G69: =MIN(G12:G64) -> 7 | H69: =MIN(H12:H64) -> 0
A70: 中央値 | B70: =MEDIAN(B12:B64) -> 225.5 | C70: =MEDIAN(C12:C64) -> 115 | D70: =MEDIAN(D12:D64) -> 135 | E70: =MEDIAN(E12:E64) -> 165.5 | F70: =MEDIAN(F12:F64) -> 146.5 | G70: =MEDIAN(G12:G64) -> 136.5 | H70: =MEDIAN(H12:H64) -> 183.5
A71: 最大値 | B71: =MAX(B12:B64) -> 291 | C71: =MAX(C12:C64) -> 173 | D71: =MAX(D12:D64) -> 190 | E71: =MAX(E12:E64) -> 223 | F71: =MAX(F12:F64) -> 203 | G71: =MAX(G12:G64) -> 198 | H71: =MAX(H12:H64) -> 252
B73: 日曜日 | C73: 月曜日 | D73: 火曜日 | E73: 水曜日 | F73: 木曜日 | G73: 金曜日 | H73: 土曜日
A74: 第0四分位数 | B74: =_xlfn.QUARTILE.INC(B12:B64, 0) -> 157 | C74: =_xlfn.QUARTILE.INC(C12:C64, 0) -> 31 | D74: =_xlfn.QUARTILE.INC(D12:D64, 0) -> 69 | E74: =_xlfn.QUARTILE.INC(E12:E64, 0) -> 100 | F74: =_xlfn.QUARTILE.INC(F12:F64, 0) -> 86 | G74: =_xlfn.QUARTILE.INC(G12:G64, 0) -> 7 | H74: =_xlfn.QUARTILE.INC(H12:H64, 0) -> 0
A75: 第一四分位数 | B75: =_xlfn.QUARTILE.INC(B12:B64, 1) -> 206.75 | C75: =_xlfn.QUARTILE.INC(C12:C64, 1) -> 89.75 | D75: =_xlfn.QUARTILE.INC(D12:D64, 1) -> 117 | E75: =_xlfn.QUARTILE.INC(E12:E64, 1) -> 148.5 | F75: =_xlfn.QUARTILE.INC(F12:F64, 1) -> 120 | G75: =_xlfn.QUARTILE.INC(G12:G64, 1) -> 115.75 | H75: =_xlfn.QUARTILE.INC(H12:H64, 1) -> 160.75
A76: 第二四分位数 | B76: =_xlfn.QUARTILE.INC(B12:B64, 2) -> 225.5 | C76: =_xlfn.QUARTILE.INC(C12:C64, 2) -> 115 | D76: =_xlfn.QUARTILE.INC(D12:D64, 2) -> 135 | E76: =_xlfn.QUARTILE.INC(E12:E64, 2) -> 165.5 | F76: =_xlfn.QUARTILE.INC(F12:F64, 2) -> 146.5 | G76: =_xlfn.QUARTILE.INC(G12:G64, 2) -> 136.5 | H76: =_xlfn.QUARTILE.INC(H12:H64, 2) -> 183.5
A77: 第三四分位数 | B77: =_xlfn.QUARTILE.INC(B12:B64, 3) -> 245.75 | C77: =_xlfn.QUARTILE.INC(C12:C64, 3) -> 138.5 | D77: =_xlfn.QUARTILE.INC(D12:D64, 3) -> 168 | E77: =_xlfn.QUARTILE.INC(E12:E64, 3) -> 191.5 | F77: =_xlfn.QUARTILE.INC(F12:F64, 3) -> 167 | G77: =_xlfn.QUARTILE.INC(G12:G64, 3) -> 168.25 | H77: =_xlfn.QUARTILE.INC(H12:H64, 3) -> 216.25
A78: 第四四分位数 | B78: =_xlfn.QUARTILE.INC(B12:B64, 4) -> 291 | C78: =_xlfn.QUARTILE.INC(C12:C64, 4) -> 173 | D78: =_xlfn.QUARTILE.INC(D12:D64, 4) -> 190 | E78: =_xlfn.QUARTILE.INC(E12:E64, 4) -> 223 | F78: =_xlfn.QUARTILE.INC(F12:F64, 4) -> 203 | G78: =_xlfn.QUARTILE.INC(G12:G64, 4) -> 198 | H78: =_xlfn.QUARTILE.INC(H12:H64, 4) -> 252
A79: 四分位範囲 | B79: =B77-B75 -> 39 | C79: =C77-C75 -> 48.75 | D79: =D77-D75 -> 51 | E79: =E77-E75 -> 43 | F79: =F77-F75 -> 47 | G79: =G77-G75 -> 52.5 | H79: =H77-H75 -> 55.5
A80: 四分位偏差 | B80: =B79/2 -> 19.5 | C80: =C79/2 -> 24.375 | D80: =D79/2 -> 25.5 | E80: =E79/2 -> 21.5 | F80: =F79/2 -> 23.5 | G80: =G79/2 -> 26.25 | H80: =H79/2 -> 27.75
A81: 四分位偏差法・LCL（下限管理限界） | B81: =B75-3*B80 -> 148.25 | C81: =C75-3*C80 -> 16.625 | D81: =D75-3*D80 -> 40.5 | E81: =E75-3*E80 -> 84 | F81: =F75-3*F80 -> 49.5 | G81: =G75-3*G80 -> 37 | H81: =H75-3*H80 -> 77.5
A82: 四分位偏差法・UCL（上限管理限界） | B82: =B77+3*B80 -> 304.25 | C82: =C77+3*C80 -> 211.625 | D82: =D77+3*D80 -> 244.5 | E82: =E77+3*E80 -> 256 | F82: =F77+3*F80 -> 237.5 | G82: =G77+3*G80 -> 247 | H82: =H77+3*H80 -> 299.5
...

Sheet 平均気温と売上の関係
C2: 平均気温(℃) | D2: 売上個数
B3: =アイスクリームの売り上げデータ!A3 -> 43466 | C3: =アイスクリームの売り上げデータ!C3 -> 5.3 | D3: =アイスクリームの売り上げデータ!G3 -> 101
B4: =アイスクリームの売り上げデータ!A4 -> 43467 | C4: =アイスクリームの売り上げデータ!C4 -> 6.2 | D4: =アイスクリームの売り上げデータ!G4 -> 119 | F4: 相関係数 | G4: =CORREL(C3:C367,D3:D367) -> 0.57082458
B5: =アイスクリームの売り上げデータ!A5 -> 43468 | C5: =アイスクリームの売り上げデータ!C5 -> 4.9 | D5: =アイスクリームの売り上げデータ!G5 -> 98
B6: =アイスクリームの売り上げデータ!A6 -> 43469 | C6: =アイスクリームの売り上げデータ!C6 -> 5.1 | D6: =アイスクリームの売り上げデータ!G6 -> 106
B7: =アイスクリームの売り上げデータ!A7 -> 43470 | C7: =アイスクリームの売り上げデータ!C7 -> 7.4 | D7: =アイスクリームの売り上げデータ!G7 -> 174
B8: =アイスクリームの売り上げデータ!A8 -> 43471 | C8: =アイスクリームの売り上げデータ!C8 -> 5.3 | D8: =アイスクリームの売り上げデータ!G8 -> 206
B9: =アイスクリームの売り上げデータ!A9 -> 43472 | C9: =アイスクリームの売り上げデータ!C9 -> 5.4 | D9: =アイスクリームの売り上げデータ!G9 -> 90
B10: =アイスクリームの売り上げデータ!A10 -> 43473 | C10: =アイスクリームの売り上げデータ!C10 -> 4.6 | D10: =アイスクリームの売り上げデータ!G10 -> 110
B11: =アイスクリームの売り上げデータ!A11 -> 43474 | C11: =アイスクリームの売り上げデータ!C11 -> 4.5 | D11: =アイスクリームの売り上げデータ!G11 -> 117
B12: =アイスクリームの売り上げデータ!A12 -> 43475 | C12: =アイスクリームの売り上げデータ!C12 -> 2 | D12: =アイスクリームの売り上げデータ!G12 -> 104
B13: =アイスクリームの売り上げデータ!A13 -> 43476 | C13: =アイスクリームの売り上げデータ!C13 -> 6.4 | D13: =アイスクリームの売り上げデータ!G13 -> 117
B14: =アイスクリームの売り上げデータ!A14 -> 43477 | C14: =アイスクリームの売り上げデータ!C14 -> 4.6 | D14: =アイスクリームの売り上げデータ!G14 -> 161
B15: =アイスクリームの売り上げデータ!A15 -> 43478 | C15: =アイスクリームの売り上げデータ!C15 -> 6.2 | D15: =アイスクリームの売り上げデータ!G15 -> 176
B16: =アイスクリームの売り上げデータ!A16 -> 43479 | C16: =アイスクリームの売り上げデータ!C16 -> 5.6 | D16: =アイスクリームの売り上げデータ!G16 -> 87
... B367: =アイスクリームの売り上げデータ!A367 -> 43830 | C367: =アイスクリームの売り上げデータ!C367 -> 8.2 | D367: =アイスクリームの売り上げデータ!G367 -> 117

Sheet 平均気温と降水量の関係
C2: 降水量 | D2: 売上個数
B3: =アイスクリームの売り上げデータ!A3 -> 43466 | C3: 0 | D3: =アイスクリームの売り上げデータ!G3 -> 101
B4: =アイスクリームの売り上げデータ!A4 -> 43467 | C4: 0 | D4: =アイスクリームの売り上げデータ!G4 -> 119 | F4: 相関係数 | G4: =CORREL(C3:C367,D3:D367) -> -0.36265195
B5: =アイスクリームの売り上げデータ!A5 -> 43468 | C5: 0 | D5: =アイスクリームの売り上げデータ!G5 -> 98
B6: =アイスクリームの売り上げデータ!A6 -> 43469 | C6: 0 | D6: =アイスクリームの売り上げデータ!G6 -> 106
B7: =アイスクリームの売り上げデータ!A7 -> 43470 | C7: 0 | D7: =アイスクリームの売り上げデータ!G7 -> 174
B8: =アイスクリームの売り上げデータ!A8 -> 43471 | C8: 0 | D8: =アイスクリームの売り上げデータ!G8 -> 206
B9: =アイスクリームの売り上げデータ!A9 -> 43472 | C9: 0 | D9: =アイスクリームの売り上げデータ!G9 -> 90
B10: =アイスクリームの売り上げデータ!A10 -> 43473 | C10: 0 | D10: =アイスクリームの売り上げデータ!G10 -> 110
B11: =アイスクリームの売り上げデータ!A11 -> 43474 | C11: 0 | D11: =アイスクリームの売り上げデータ!G11 -> 117
B12: =アイスクリームの売り上げデータ!A12 -> 43475 | C12: 0 | D12: =アイスクリームの売り上げデータ!G12 -> 104
B13: =アイスクリームの売り上げデータ!A13 -> 43476 | C13: 0 | D13: =アイスクリームの売り上げデータ!G13 -> 117
B14: =アイスクリームの売り上げデータ!A14 -> 43477 | C14: 0 | D14: =アイスクリームの売り上げデータ!G14 -> 161
B15: =アイスクリームの売り上げデータ!A15 -> 43478 | C15: 0 | D15: =アイスクリームの売り上げデータ!G15 -> 176
B16: =アイスクリームの売り上げデータ!A16 -> 43479 | C16: 0 | D16: =アイスクリームの売り上げデータ!G16 -> 87
... B367: =アイスクリームの売り上げデータ!A367 -> 43830 | C367: 0 | D367: =アイスクリームの売り上げデータ!G367 -> 117

Sheet 相関係数
I2: 日 | J2: 曜日 | K2: 土日フラグ
B3: 曜日 | C3: 平均気温(℃) | D3: 最高気温(℃) | E3: 最低気温(℃) | F3: 降水量の合計(mm) | G3: 売上個数 | I3: =アイスクリームの売り上げデータ!A3 -> 43466 | J3: =アイスクリームの売り上げデータ!B3 -> 3 | K3: =IF(OR(J3=1,J3=7),1,0) -> 0
A4: 曜日 | B4: =CORREL(アイスクリームの売り上げデータ!$B3:$B367,アイスクリームの売り上げデータ!B3:B367) -> 1 | C4: =CORREL(アイスクリームの売り上げデータ!$B3:$B367,アイスクリームの売り上げデータ!C3:C367) -> -0.0072191368 | D4: =CORREL(アイスクリームの売り上げデータ!$B3:$B367,アイスクリームの売り上げデータ!D3:D367) -> -0.014165839 | E4: =CORREL(アイスクリームの売り上げデータ!$B3:$B367,アイスクリームの売り上げデータ!E3:E367) -> 0.00034339059 | F4: =CORREL(アイスクリームの売り上げデータ!$B3:$B367,アイスクリームの売り上げデータ!F3:F367) -> 0.012552139 | G4: =CORREL(アイスクリームの売り上げデータ!$B3:$B367,アイスクリームの売り上げデータ!G3:G367) -> -0.099383888 | I4: =アイスクリームの売り上げデータ!A4 -> 43467 | J4: =アイスクリームの売り上げデータ!B4 -> 4 | K4: =IF(OR(J4=1,J4=7),1,0) -> 0
A5: 平均気温(℃) | B5: =CORREL(アイスクリームの売り上げデータ!$C3:$C367,アイスクリームの売り上げデータ!B3:B367) -> -0.0072191368 | C5: =CORREL(アイスクリームの売り上げデータ!$C3:$C367,アイスクリームの売り上げデータ!C3:C367) -> 1 | D5: =CORREL(アイスクリームの売り上げデータ!$C3:$C367,アイスクリームの売り上げデータ!D3:D367) -> 0.98120759 | E5: =CORREL(アイスクリームの売り上げデータ!$C3:$C367,アイスクリームの売り上げデータ!E3:E367) -> 0.98098585 | F5: =CORREL(アイスクリームの売り上げデータ!$C3:$C367,アイスクリームの売り上げデータ!F3:F367) -> 0.059399856 | G5: =CORREL(アイスクリームの売り上げデータ!$C3:$C367,アイスクリームの売り上げデータ!G3:G367) -> 0.57082458 | I5: =アイスクリームの売り上げデータ!A5 -> 43468 | J5: =アイスクリームの売り上げデータ!B5 -> 5 | K5: =IF(OR(J5=1,J5=7),1,0) -> 0
A6: 最高気温(℃) | B6: =CORREL(アイスクリームの売り上げデータ!$D3:$D367,アイスクリームの売り上げデータ!B3:B367) -> -0.014165839 | C6: =CORREL(アイスクリームの売り上げデータ!$D3:$D367,アイスクリームの売り上げデータ!C3:C367) -> 0.98120759 | D6: =CORREL(アイスクリームの売り上げデータ!$D3:$D367,アイスクリームの売り上げデータ!D3:D367) -> 1 | E6: =CORREL(アイスクリームの売り上げデータ!$D3:$D367,アイスクリームの売り上げデータ!E3:E367) -> 0.93374873 | F6: =CORREL(アイスクリームの売り上げデータ!$D3:$D367,アイスクリームの売り上げデータ!F3:F367) -> 0.0094211529 | G6: =CORREL(アイスクリームの売り上げデータ!$D3:$D367,アイスクリームの売り上げデータ!G3:G367) -> 0.57899221 | I6: =アイスクリームの売り上げデータ!A6 -> 43469 | J6: =アイスクリームの売り上げデータ!B6 -> 6 | K6: =IF(OR(J6=1,J6=7),1,0) -> 0
A7: 最低気温(℃) | B7: =CORREL(アイスクリームの売り上げデータ!$E3:$E367,アイスクリームの売り上げデータ!B3:B367) -> 0.00034339059 | C7: =CORREL(アイスクリームの売り上げデータ!$E3:$E367,アイスクリームの売り上げデータ!C3:C367) -> 0.98098585 | D7: =CORREL(アイスクリームの売り上げデータ!$E3:$E367,アイスクリームの売り上げデータ!D3:D367) -> 0.93374873 | E7: =CORREL(アイスクリームの売り上げデータ!$E3:$E367,アイスクリームの売り上げデータ!E3:E367) -> 1 | F7: =CORREL(アイスクリームの売り上げデータ!$E3:$E367,アイスクリームの売り上げデータ!F3:F367) -> 0.10305647 | G7: =CORREL(アイスクリームの売り上げデータ!$E3:$E367,アイスクリームの売り上げデータ!G3:G367) -> 0.54176919 | I7: =アイスクリームの売り上げデータ!A7 -> 43470 | J7: =アイスクリームの売り上げデータ!B7 -> 7 | K7: =IF(OR(J7=1,J7=7),1,0) -> 1
A8: 降水量の合計(mm) | B8: =CORREL(アイスクリームの売り上げデータ!$F3:$F367,アイスクリームの売り上げデータ!B3:B367) -> 0.012552139 | C8: =CORREL(アイスクリームの売り上げデータ!$F3:$F367,アイスクリームの売り上げデータ!C3:C367) -> 0.059399856 | D8: =CORREL(アイスクリームの売り上げデータ!$F3:$F367,アイスクリームの売り上げデータ!D3:D367) -> 0.0094211529 | E8: =CORREL(アイスクリームの売り上げデータ!$F3:$F367,アイスクリームの売り上げデータ!E3:E367) -> 0.10305647 | F8: =CORREL(アイスクリームの売り上げデータ!$F3:$F367,アイスクリームの売り上げデータ!F3:F367) -> 1 | G8: =CORREL(アイスクリームの売り上げデータ!$F3:$F367,アイスクリームの売り上げデータ!G3:G367) -> -0.36265195 | I8: =アイスクリームの売り上げデータ!A8 -> 43471 | J8: =アイスクリームの売り上げデータ!B8 -> 1 | K8: =IF(OR(J8=1,J8=7),1,0) -> 1
A9: 売上個数 | B9: =CORREL(アイスクリームの売り上げデータ!$G3:$G367,アイスクリームの売り上げデータ!B3:B367) -> -0.099383888 | C9: =CORREL(アイスクリームの売り上げデータ!$G3:$G367,アイスクリームの売り上げデータ!C3:C367) -> 0.57082458 | D9: =CORREL(アイスクリームの売り上げデータ!$G3:$G367,アイスクリームの売り上げデータ!D3:D367) -> 0.57899221 | E9: =CORREL(アイスクリームの売り上げデータ!$G3:$G367,アイスクリームの売り上げデータ!E3:E367) -> 0.54176919 | F9: =CORREL(アイスクリームの売り上げデータ!$G3:$G367,アイスクリームの売り上げデータ!F3:F367) -> -0.36265195 | G9: =CORREL(アイスクリームの売り上げデータ!$G3:$G367,アイスクリームの売り上げデータ!G3:G367) -> 1 | I9: =アイスクリームの売り上げデータ!A9 -> 43472 | J9: =アイスクリームの売り上げデータ!B9 -> 2 | K9: =IF(OR(J9=1,J9=7),1,0) -> 0
I10: =アイスクリームの売り上げデータ!A10 -> 43473 | J10: =アイスクリームの売り上げデータ!B10 -> 3 | K10: =IF(OR(J10=1,J10=7),1,0) -> 0
A11: 土日と売上の相関係数 | B11: =CORREL(相関係数!K3:K367,アイスクリームの売り上げデータ!G3:G367) -> 0.59632818 | I11: =アイスクリームの売り上げデータ!A11 -> 43474 | J11: =アイスクリームの売り上げデータ!B11 -> 4 | K11: =IF(OR(J11=1,J11=7),1,0) -> 0
I12: =アイスクリームの売り上げデータ!A12 -> 43475 | J12: =アイスクリームの売り上げデータ!B12 -> 5 | K12: =IF(OR(J12=1,J12=7),1,0) -> 0
I13: =アイスクリームの売り上げデータ!A13 -> 43476 | J13: =アイスクリームの売り上げデータ!B13 -> 6 | K13: =IF(OR(J13=1,J13=7),1,0) -> 0
I14: =アイスクリームの売り上げデータ!A14 -> 43477 | J14: =アイスクリームの売り上げデータ!B14 -> 7 | K14: =IF(OR(J14=1,J14=7),1,0) -> 1
I15: =アイスクリームの売り上げデータ!A15 -> 43478 | J15: =アイスクリームの売り上げデータ!B15 -> 1 | K15: =IF(OR(J15=1,J15=7),1,0) -> 1
I16: =アイスクリームの売り上げデータ!A16 -> 43479 | J16: =アイスクリームの売り上げデータ!B16 -> 2 | K16: =IF(OR(J16=1,J16=7),1,0) -> 0
I17: =アイスクリームの売り上げデータ!A17 -> 43480 | J17: =アイスクリームの売り上げデータ!B17 -> 3 | K17: =IF(OR(J17=1,J17=7),1,0) -> 0
I18: =アイスクリームの売り上げデータ!A18 -> 43481 | J18: =アイスクリームの売り上げデータ!B18 -> 4 | K18: =IF(OR(J18=1,J18=7),1,0) -> 0
I19: =アイスクリームの売り上げデータ!A19 -> 43482 | J19: =アイスクリームの売り上げデータ!B19 -> 5 | K19: =IF(OR(J19=1,J19=7),1,0) -> 0
I20: =アイスクリームの売り上げデータ!A20 -> 43483 | J20: =アイスクリームの売り上げデータ!B20 -> 6 | K20: =IF(OR(J20=1,J20=7),1,0) -> 0
I21: =アイスクリームの売り上げデータ!A21 -> 43484 | J21: =アイスクリームの売り上げデータ!B21 -> 7 | K21: =IF(OR(J21=1,J21=7),1,0) -> 1
I22: =アイスクリームの売り上げデータ!A22 -> 43485 | J22: =アイスクリームの売り上げデータ!B22 -> 1 | K22: =IF(OR(J22=1,J22=7),1,0) -> 1
I23: =アイスクリームの売り上げデータ!A23 -> 43486 | J23: =アイスクリームの売り上げデータ!B23 -> 2 | K23: =IF(OR(J23=1,J23=7),1,0) -> 0
... I367: =アイスクリームの売り上げデータ!A367 -> 43830 | J367: =アイスクリームの売り上げデータ!B367 -> 3 | K367: =IF(OR(J367=1,J367=7),1,0) -> 0

Sheet 気温による線形回帰
C2: 平均気温(℃) | D2: 売上個数 | F2: 気温 | G2: 予測数
B3: =アイスクリームの売り上げデータ!A3 -> 43466 | C3: =アイスクリームの売り上げデータ!C3 -> 5.3 | D3: =アイスクリームの売り上げデータ!G3 -> 101 | F3: 0 | G3: =F3*K$5+K$6 -> 102.36877
B4: =アイスクリームの売り上げデータ!A4 -> 43467 | C4: =アイスクリームの売り上げデータ!C4 -> 6.2 | D4: =アイスクリームの売り上げデータ!G4 -> 119 | F4: 1 | G4: =F4*K$5+K$6 -> 105.8253 | J4: 相関係数 | K4: =CORREL(C3:C367,D3:D367) -> 0.57082458
B5: =アイスクリームの売り上げデータ!A5 -> 43468 | C5: =アイスクリームの売り上げデータ!C5 -> 4.9 | D5: =アイスクリームの売り上げデータ!G5 -> 98 | F5: 2 | G5: =F5*K$5+K$6 -> 109.28184 | J5: 傾き | K5: =SLOPE(D3:D367,C3:C367) -> 3.4565324
B6: =アイスクリームの売り上げデータ!A6 -> 43469 | C6: =アイスクリームの売り上げデータ!C6 -> 5.1 | D6: =アイスクリームの売り上げデータ!G6 -> 106 | F6: 3 | G6: =F6*K$5+K$6 -> 112.73837 | J6: 切片 | K6: =INTERCEPT(D3:D367,C3:C367) -> 102.36877
B7: =アイスクリームの売り上げデータ!A7 -> 43470 | C7: =アイスクリームの売り上げデータ!C7 -> 7.4 | D7: =アイスクリームの売り上げデータ!G7 -> 174 | F7: 4 | G7: =F7*K$5+K$6 -> 116.1949
B8: =アイスクリームの売り上げデータ!A8 -> 43471 | C8: =アイスクリームの売り上げデータ!C8 -> 5.3 | D8: =アイスクリームの売り上げデータ!G8 -> 206 | F8: 5 | G8: =F8*K$5+K$6 -> 119.65143
B9: =アイスクリームの売り上げデータ!A9 -> 43472 | C9: =アイスクリームの売り上げデータ!C9 -> 5.4 | D9: =アイスクリームの売り上げデータ!G9 -> 90 | F9: 6 | G9: =F9*K$5+K$6 -> 123.10796
B10: =アイスクリームの売り上げデータ!A10 -> 43473 | C10: =アイスクリームの売り上げデータ!C10 -> 4.6 | D10: =アイスクリームの売り上げデータ!G10 -> 110 | F10: 7 | G10: =F10*K$5+K$6 -> 126.5645
B11: =アイスクリームの売り上げデータ!A11 -> 43474 | C11: =アイスクリームの売り上げデータ!C11 -> 4.5 | D11: =アイスクリームの売り上げデータ!G11 -> 117 | F11: 8 | G11: =F11*K$5+K$6 -> 130.02103
B12: =アイスクリームの売り上げデータ!A12 -> 43475 | C12: =アイスクリームの売り上げデータ!C12 -> 2 | D12: =アイスクリームの売り上げデータ!G12 -> 104 | F12: 9 | G12: =F12*K$5+K$6 -> 133.47756
B13: =アイスクリームの売り上げデータ!A13 -> 43476 | C13: =アイスクリームの売り上げデータ!C13 -> 6.4 | D13: =アイスクリームの売り上げデータ!G13 -> 117 | F13: 10 | G13: =F13*K$5+K$6 -> 136.93409
B14: =アイスクリームの売り上げデータ!A14 -> 43477 | C14: =アイスクリームの売り上げデータ!C14 -> 4.6 | D14: =アイスクリームの売り上げデータ!G14 -> 161 | F14: 11 | G14: =F14*K$5+K$6 -> 140.39063
B15: =アイスクリームの売り上げデータ!A15 -> 43478 | C15: =アイスクリームの売り上げデータ!C15 -> 6.2 | D15: =アイスクリームの売り上げデータ!G15 -> 176 | F15: 12 | G15: =F15*K$5+K$6 -> 143.84716
B16: =アイスクリームの売り上げデータ!A16 -> 43479 | C16: =アイスクリームの売り上げデータ!C16 -> 5.6 | D16: =アイスクリームの売り上げデータ!G16 -> 87 | F16: 13 | G16: =F16*K$5+K$6 -> 147.30369
B17: =アイスクリームの売り上げデータ!A17 -> 43480 | C17: =アイスクリームの売り上げデータ!C17 -> 5.6 | D17: =アイスクリームの売り上げデータ!G17 -> 100 | F17: 14 | G17: =F17*K$5+K$6 -> 150.76022
B18: =アイスクリームの売り上げデータ!A18 -> 43481 | C18: =アイスクリームの売り上げデータ!C18 -> 6.6 | D18: =アイスクリームの売り上げデータ!G18 -> 130 | F18: 15 | G18: =F18*K$5+K$6 -> 154.21676
... B48: =アイスクリームの売り上げデータ!A48 -> 43511 | C48: =アイスクリームの売り上げデータ!C48 -> 3 | D48: =アイスクリームの売り上げデータ!G48 -> 98 | F48: 45 | G48: =F48*K$5+K$6 -> 257.91273
B49: =アイスクリームの売り上げデータ!A49 -> 43512 | C49: =アイスクリームの売り上げデータ!C49 -> 6.8 | D49: =アイスクリームの売り上げデータ!G49 -> 166
B50: =アイスクリームの売り上げデータ!A50 -> 43513 | C50: =アイスクリームの売り上げデータ!C50 -> 6.4 | D50: =アイスクリームの売り上げデータ!G50 -> 186
B51: =アイスクリームの売り上げデータ!A51 -> 43514 | C51: =アイスクリームの売り上げデータ!C51 -> 8.2 | D51: =アイスクリームの売り上げデータ!G51 -> 90
B52: =アイスクリームの売り上げデータ!A52 -> 43515 | C52: =アイスクリームの売り上げデータ!C52 -> 9.1 | D52: =アイスクリームの売り上げデータ!G52 -> 127
B53: =アイスクリームの売り上げデータ!A53 -> 43516 | C53: =アイスクリームの売り上げデータ!C53 -> 11.6 | D53: =アイスクリームの売り上げデータ!G53 -> 165
B54: =アイスクリームの売り上げデータ!A54 -> 43517 | C54: =アイスクリームの売り上げデータ!C54 -> 10.3 | D54: =アイスクリームの売り上げデータ!G54 -> 115
B55: =アイスクリームの売り上げデータ!A55 -> 43518 | C55: =アイスクリームの売り上げデータ!C55 -> 9.3 | D55: =アイスクリームの売り上げデータ!G55 -> 125
B56: =アイスクリームの売り上げデータ!A56 -> 43519 | C56: =アイスクリームの売り上げデータ!C56 -> 8.9 | D56: =アイスクリームの売り上げデータ!G56 -> 173
B57: =アイスクリームの売り上げデータ!A57 -> 43520 | C57: =アイスクリームの売り上げデータ!C57 -> 8.8 | D57: =アイスクリームの売り上げデータ!G57 -> 182
B58: =アイスクリームの売り上げデータ!A58 -> 43521 | C58: =アイスクリームの売り上げデータ!C58 -> 11.3 | D58: =アイスクリームの売り上げデータ!G58 -> 109
B59: =アイスクリームの売り上げデータ!A59 -> 43522 | C59: =アイスクリームの売り上げデータ!C59 -> 10.2 | D59: =アイスクリームの売り上げデータ!G59 -> 116
B60: =アイスクリームの売り上げデータ!A60 -> 43523 | C60: =アイスクリームの売り上げデータ!C60 -> 7.7 | D60: =アイスクリームの売り上げデータ!G60 -> 143
... B367: =アイスクリームの売り上げデータ!A367 -> 43830 | C367: =アイスクリームの売り上げデータ!C367 -> 8.2 | D367: =アイスクリームの売り上げデータ!G367 -> 117

Sheet 重回帰分析
C2: 土日 | D2: 平均気温(℃) | E2: 最高気温(℃) | F2: 最低気温(℃) | G2: 降水量の合計(mm) | H2: 売上個数 | I2: 重回帰予測 | J2: 誤差
B3: 43466 | C3: =IF(OR(アイスクリームの売り上げデータ!B3=1,アイスクリームの売り上げデータ!B3=7),1,0) -> 0 | D3: =アイスクリームの売り上げデータ!C3 -> 5.3 | E3: =アイスクリームの売り上げデータ!D3 -> 10.7 | F3: =アイスクリームの売り上げデータ!E3 -> 0.9 | G3: =アイスクリームの売り上げデータ!F3 -> 0 | H3: =アイスクリームの売り上げデータ!G3 -> 101 | I3: =重回帰の係数!$B$18*重回帰分析!C3+重回帰の係数!$B$19*重回帰分析!D3+重回帰の係数!$B$20*重回帰分析!E3+重回帰の係数!$B$21*重回帰分析!F3+重回帰の係数!$B$22*重回帰分析!G3+重回帰の係数!$B$17 -> 106.39493 | J3: =ABS(H3-I3) -> 5.394933
B4: 43467 | C4: =IF(OR(アイスクリームの売り上げデータ!B4=1,アイスクリームの売り上げデータ!B4=7),1,0) -> 0 | D4: =アイスクリームの売り上げデータ!C4 -> 6.2 | E4: =アイスクリームの売り上げデータ!D4 -> 10.9 | F4: =アイスクリームの売り上げデータ!E4 -> 2.2 | G4: =アイスクリームの売り上げデータ!F4 -> 0 | H4: =アイスクリームの売り上げデータ!G4 -> 119 | I4: =重回帰の係数!$B$18*重回帰分析!C4+重回帰の係数!$B$19*重回帰分析!D4+重回帰の係数!$B$20*重回帰分析!E4+重回帰の係数!$B$21*重回帰分析!F4+重回帰の係数!$B$22*重回帰分析!G4+重回帰の係数!$B$17 -> 109.50387 | J4: =ABS(H4-I4) -> 9.4961308 | L4: 平均予測誤差 | M4: =AVERAGE(J3:J367) -> 14.264364
B5: 43468 | C5: =IF(OR(アイスクリームの売り上げデータ!B5=1,アイスクリームの売り上げデータ!B5=7),1,0) -> 0 | D5: =アイスクリームの売り上げデータ!C5 -> 4.9 | E5: =アイスクリームの売り上げデータ!D5 -> 10.9 | F5: =アイスクリームの売り上げデータ!E5 -> -0.3 | G5: =アイスクリームの売り上げデータ!F5 -> 0 | H5: =アイスクリームの売り上げデータ!G5 -> 98 | I5: =重回帰の係数!$B$18*重回帰分析!C5+重回帰の係数!$B$19*重回帰分析!D5+重回帰の係数!$B$20*重回帰分析!E5+重回帰の係数!$B$21*重回帰分析!F5+重回帰の係数!$B$22*重回帰分析!G5+重回帰の係数!$B$17 -> 104.70398 | J5: =ABS(H5-I5) -> 6.7039838
B6: 43469 | C6: =IF(OR(アイスクリームの売り上げデータ!B6=1,アイスクリームの売り上げデータ!B6=7),1,0) -> 0 | D6: =アイスクリームの売り上げデータ!C6 -> 5.1 | E6: =アイスクリームの売り上げデータ!D6 -> 9.8 | F6: =アイスクリームの売り上げデータ!E6 -> 0.2 | G6: =アイスクリームの売り上げデータ!F6 -> 0 | H6: =アイスクリームの売り上げデータ!G6 -> 106 | I6: =重回帰の係数!$B$18*重回帰分析!C6+重回帰の係数!$B$19*重回帰分析!D6+重回帰の係数!$B$20*重回帰分析!E6+重回帰の係数!$B$21*重回帰分析!F6+重回帰の係数!$B$22*重回帰分析!G6+重回帰の係数!$B$17 -> 104.79285 | J6: =ABS(H6-I6) -> 1.2071529
B7: 43470 | C7: =IF(OR(アイスクリームの売り上げデータ!B7=1,アイスクリームの売り上げデータ!B7=7),1,0) -> 1 | D7: =アイスクリームの売り上げデータ!C7 -> 7.4 | E7: =アイスクリームの売り上げデータ!D7 -> 14 | F7: =アイスクリームの売り上げデータ!E7 -> 0.9 | G7: =アイスクリームの売り上げデータ!F7 -> 0 | H7: =アイスクリームの売り上げデータ!G7 -> 174 | I7: =重回帰の係数!$B$18*重回帰分析!C7+重回帰の係数!$B$19*重回帰分析!D7+重回帰の係数!$B$20*重回帰分析!E7+重回帰の係数!$B$21*重回帰分析!F7+重回帰の係数!$B$22*重回帰分析!G7+重回帰の係数!$B$17 -> 177.51042 | J7: =ABS(H7-I7) -> 3.5104204
B8: 43471 | C8: =IF(OR(アイスクリームの売り上げデータ!B8=1,アイスクリームの売り上げデータ!B8=7),1,0) -> 1 | D8: =アイスクリームの売り上げデータ!C8 -> 5.3 | E8: =アイスクリームの売り上げデータ!D8 -> 8 | F8: =アイスクリームの売り上げデータ!E8 -> 2.4 | G8: =アイスクリームの売り上げデータ!F8 -> 0 | H8: =アイスクリームの売り上げデータ!G8 -> 206 | I8: =重回帰の係数!$B$18*重回帰分析!C8+重回帰の係数!$B$19*重回帰分析!D8+重回帰の係数!$B$20*重回帰分析!E8+重回帰の係数!$B$21*重回帰分析!F8+重回帰の係数!$B$22*重回帰分析!G8+重回帰の係数!$B$17 -> 170.19279 | J8: =ABS(H8-I8) -> 35.807205
B9: 43472 | C9: =IF(OR(アイスクリームの売り上げデータ!B9=1,アイスクリームの売り上げデータ!B9=7),1,0) -> 0 | D9: =アイスクリームの売り上げデータ!C9 -> 5.4 | E9: =アイスクリームの売り上げデータ!D9 -> 10.6 | F9: =アイスクリームの売り上げデータ!E9 -> 0.4 | G9: =アイスクリームの売り上げデータ!F9 -> 0 | H9: =アイスクリームの売り上げデータ!G9 -> 90 | I9: =重回帰の係数!$B$18*重回帰分析!C9+重回帰の係数!$B$19*重回帰分析!D9+重回帰の係数!$B$20*重回帰分析!E9+重回帰の係数!$B$21*重回帰分析!F9+重回帰の係数!$B$22*重回帰分析!G9+重回帰の係数!$B$17 -> 106.13543 | J9: =ABS(H9-I9) -> 16.13543
B10: 43473 | C10: =IF(OR(アイスクリームの売り上げデータ!B10=1,アイスクリームの売り上げデータ!B10=7),1,0) -> 0 | D10: =アイスクリームの売り上げデータ!C10 -> 4.6 | E10: =アイスクリームの売り上げデータ!D10 -> 9.8 | F10: =アイスクリームの売り上げデータ!E10 -> 0.7 | G10: =アイスクリームの売り上げデータ!F10 -> 0 | H10: =アイスクリームの売り上げデータ!G10 -> 110 | I10: =重回帰の係数!$B$18*重回帰分析!C10+重回帰の係数!$B$19*重回帰分析!D10+重回帰の係数!$B$20*重回帰分析!E10+重回帰の係数!$B$21*重回帰分析!F10+重回帰の係数!$B$22*重回帰分析!G10+重回帰の係数!$B$17 -> 104.13143 | J10: =ABS(H10-I10) -> 5.8685715
B11: 43474 | C11: =IF(OR(アイスクリームの売り上げデータ!B11=1,アイスクリームの売り上げデータ!B11=7),1,0) -> 0 | D11: =アイスクリームの売り上げデータ!C11 -> 4.5 | E11: =アイスクリームの売り上げデータ!D11 -> 8 | F11: =アイスクリームの売り上げデータ!E11 -> 1 | G11: =アイスクリームの売り上げデータ!F11 -> 0 | H11: =アイスクリームの売り上げデータ!G11 -> 117 | I11: =重回帰の係数!$B$18*重回帰分析!C11+重回帰の係数!$B$19*重回帰分析!D11+重回帰の係数!$B$20*重回帰分析!E11+重回帰の係数!$B$21*重回帰分析!F11+重回帰の係数!$B$22*重回帰分析!G11+重回帰の係数!$B$17 -> 102.94526 | J11: =ABS(H11-I11) -> 14.054736
B12: 43475 | C12: =IF(OR(アイスクリームの売り上げデータ!B12=1,アイスクリームの売り上げデータ!B12=7),1,0) -> 0 | D12: =アイスクリームの売り上げデータ!C12 -> 2 | E12: =アイスクリームの売り上げデータ!D12 -> 5.2 | F12: =アイスクリームの売り上げデータ!E12 -> -1.2 | G12: =アイスクリームの売り上げデータ!F12 -> 0 | H12: =アイスクリームの売り上げデータ!G12 -> 104 | I12: =重回帰の係数!$B$18*重回帰分析!C12+重回帰の係数!$B$19*重回帰分析!D12+重回帰の係数!$B$20*重回帰分析!E12+重回帰の係数!$B$21*重回帰分析!F12+重回帰の係数!$B$22*重回帰分析!G12+重回帰の係数!$B$17 -> 93.936904 | J12: =ABS(H12-I12) -> 10.063096
B13: 43476 | C13: =IF(OR(アイスクリームの売り上げデータ!B13=1,アイスクリームの売り上げデータ!B13=7),1,0) -> 0 | D13: =アイスクリームの売り上げデータ!C13 -> 6.4 | E13: =アイスクリームの売り上げデータ!D13 -> 12.2 | F13: =アイスクリームの売り上げデータ!E13 -> -0.2 | G13: =アイスクリームの売り上げデータ!F13 -> 0 | H13: =アイスクリームの売り上げデータ!G13 -> 117 | I13: =重回帰の係数!$B$18*重回帰分析!C13+重回帰の係数!$B$19*重回帰分析!D13+重回帰の係数!$B$20*重回帰分析!E13+重回帰の係数!$B$21*重回帰分析!F13+重回帰の係数!$B$22*重回帰分析!G13+重回帰の係数!$B$17 -> 108.86338 | J13: =ABS(H13-I13) -> 8.1366158
B14: 43477 | C14: =IF(OR(アイスクリームの売り上げデータ!B14=1,アイスクリームの売り上げデータ!B14=7),1,0) -> 1 | D14: =アイスクリームの売り上げデータ!C14 -> 4.6 | E14: =アイスクリームの売り上げデータ!D14 -> 6.2 | F14: =アイスクリームの売り上げデータ!E14 -> 2.7 | G14: =アイスクリームの売り上げデータ!F14 -> 0 | H14: =アイスクリームの売り上げデータ!G14 -> 161 | I14: =重回帰の係数!$B$18*重回帰分析!C14+重回帰の係数!$B$19*重回帰分析!D14+重回帰の係数!$B$20*重回帰分析!E14+重回帰の係数!$B$21*重回帰分析!F14+重回帰の係数!$B$22*重回帰分析!G14+重回帰の係数!$B$17 -> 167.72658 | J14: =ABS(H14-I14) -> 6.726581
B15: 43478 | C15: =IF(OR(アイスクリームの売り上げデータ!B15=1,アイスクリームの売り上げデータ!B15=7),1,0) -> 1 | D15: =アイスクリームの売り上げデータ!C15 -> 6.2 | E15: =アイスクリームの売り上げデータ!D15 -> 10.1 | F15: =アイスクリームの売り上げデータ!E15 -> 3.9 | G15: =アイスクリームの売り上げデータ!F15 -> 0 | H15: =アイスクリームの売り上げデータ!G15 -> 176 | I15: =重回帰の係数!$B$18*重回帰分析!C15+重回帰の係数!$B$19*重回帰分析!D15+重回帰の係数!$B$20*重回帰分析!E15+重回帰の係数!$B$21*重回帰分析!F15+重回帰の係数!$B$22*重回帰分析!G15+重回帰の係数!$B$17 -> 174.7474 | J15: =ABS(H15-I15) -> 1.2526021
B16: 43479 | C16: =IF(OR(アイスクリームの売り上げデータ!B16=1,アイスクリームの売り上げデータ!B16=7),1,0) -> 0 | D16: =アイスクリームの売り上げデータ!C16 -> 5.6 | E16: =アイスクリームの売り上げデータ!D16 -> 9.8 | F16: =アイスクリームの売り上げデータ!E16 -> 1.3 | G16: =アイスクリームの売り上げデータ!F16 -> 0 | H16: =アイスクリームの売り上げデータ!G16 -> 87 | I16: =重回帰の係数!$B$18*重回帰分析!C16+重回帰の係数!$B$19*重回帰分析!D16+重回帰の係数!$B$20*重回帰分析!E16+重回帰の係数!$B$21*重回帰分析!F16+重回帰の係数!$B$22*重回帰分析!G16+重回帰の係数!$B$17 -> 106.75119 | J16: =ABS(H16-I16) -> 19.751191
... B367: 43830 | C367: =IF(OR(アイスクリームの売り上げデータ!B367=1,アイスクリームの売り上げデータ!B367=7),1,0) -> 0 | D367: =アイスクリームの売り上げデータ!C367 -> 8.2 | E367: =アイスクリームの売り上げデータ!D367 -> 16.5 | F367: =アイスクリームの売り上げデータ!E367 -> 3.7 | G367: =アイスクリームの売り上げデータ!F367 -> 0 | H367: =アイスクリームの売り上げデータ!G367 -> 117 | I367: =重回帰の係数!$B$18*重回帰分析!C367+重回帰の係数!$B$19*重回帰分析!D367+重回帰の係数!$B$20*重回帰分析!E367+重回帰の係数!$B$21*重回帰分析!F367+重回帰の係数!$B$22*重回帰分析!G367+重回帰の係数!$B$17 -> 118.76967 | J367: =ABS(H367-I367) -> 1.7696666

Sheet 重回帰の係数
A1: 概要
A3: 回帰統計
A4: 重相関 R | B4: 0.92778531
A5: 重決定 R2 | B5: 0.86078558
A6: 補正 R2 | B6: 0.85884666 | C6: 補正 R2（自由度調整済み決定係数）：1に近づくほど、XはYの決定に影響を与えているといえる。0.6-0.8くらいが理想。1だと単純すぎて分析する必要なし。
A7: 標準誤差 | B7: 17.787505
A8: 観測数 | B8: 365
A10: 分散分析表
B11: 自由度 | C11: 変動 | D11: 分散 | E11: 観測された分散比 | F11: 有意 F
A12: 回帰 | B12: 5 | C12: 702320.38 | D12: 140464.08 | E12: 443.95115 | F12: 2.859082e-151
A13: 残差 | B13: 359 | C13: 113585.93 | D13: 316.39534
A14: 合計 | B14: 364 | C14: 815906.3
B16: 係数 | C16: 標準誤差 | D16: t | E16: P-値 | F16: 下限 95% | G16: 上限 95% | H16: 下限 95.0% | I16: 上限 95.0%
A17: 切片 | B17: 87.129889 | C17: 3.6365105 | D17: 23.959752 | E17: 1.8564768e-76 | F17: 79.97835 | G17: 94.281429 | H17: 79.97835 | I17: 94.281429
A18: 土日 | B18: 64.405989 | C18: 2.0654044 | D18: 31.183234 | E18: 3.2983267e-104 | F18: 60.344177 | G18: 68.4678 | H18: 60.344177 | I18: 68.4678
A19: 平均気温(℃) | B19: 2.1334154 | C19: 1.7858643 | D19: 1.1946122 | E19: 0.23302722 | F19: -1.3786546 | G19: 5.6454854 | H19: -1.3786546 | I19: 5.6454854
A20: 最高気温(℃) | B20: 0.67555347 | C20: 0.95467444 | D20: 0.70762706 | E20: 0.479636 | F20: -1.2019035 | G20: 2.5530104 | H20: -1.2019035 | I20: 2.5530104
A21: 最低気温(℃) | B21: 0.81057816 | C21: 0.93051543 | D21: 0.87110662 | E21: 0.38427808 | F21: -1.0193679 | G21: 2.6405242 | H21: -1.0193679 | I21: 2.6405242
A22: 降水量の合計(mm) | B22: -1.1358251 | C22: 0.055413435 | D22: -20.497287 | E22: 2.2478865e-62 | F22: -1.2448008 | G22: -1.0268493 | H22: -1.2448008 | I22: -1.0268493
